Workbook

Sheet TOC
D3: Table of Contents
D4: Full Service Offerings
D5: A&U
D6: Ad Testing
D7: Concept Testing
D8: Competitive Benchmarking
D9: Competitive Landscape / Market Landscape
D10: Message Testing w/ Max Diff
D11: Product Development w/ Conjoint
D12: Product Development w/ MaxDiff
D13: Segmentation
D15: Ad-Hoc Services
... D24: Jump to List View

Sheet Sheet2
D4: Main | E4: Booster | F4: Booster CPI
D5: 3205 | E5: =100*F5 -> 2926.6667 | F5: =878/30 -> 29.266667
D6: 3205 | E6: =100*F6 -> 2925 | F6: =585/20 -> 29.25
D7: 3205 | E7: =100*F7 -> 2927.5 | F7: =1171/40 -> 29.275
E8: =sum(D5:E7) -> 18394.167
E9: 500
E10: =E8+E9 -> 18894.167

Sheet Use Case Cost Overview & Calcul
D3: Cost Overview for Full-Service Research
B5: Base Full-Service Bundle Costs | D5: Tier 1 - Standard | E5: Tier 2 - Standard Plus | F5: Tier 3 - Advanced | G5: Tier 4 - Custom
B6: A&U | D6: ='A&U'!C35 -> $24,900 + n*(CPI*2.5+$0.68) | E6: ='A&U'!D35 -> $28,400 + n*(CPI*2.5+$0.68) | F6: ='A&U'!E35 -> $35,900 + n*(CPI*2.5+$0.68) | G6: ='A&U'!F35 -> Custom
B7: Ad Testing | D7: ='Ad Testing'!C36 -> $24,500 + n*(CPI*2.5+$0.68) | E7: ='Ad Testing'!D36 -> $27,000 + n*(CPI*2.5+$2.04) | F7: ='Ad Testing'!E36 -> $32,900 + n*(CPI*2.5+$2.04) | G7: ='Ad Testing'!F36 -> Custom
B8: Brand Tracking
B9: Concept Testing | D9: ='Concept Testing'!C35 -> $24,500 + n*(CPI*2.5+$0.68) | E9: ='Concept Testing'!D35 -> $27,000 + n*(CPI*2.5+$2.04) | F9: ='Concept Testing'!E35 -> $32,900 + n*(CPI*2.5+$2.04) | G9: ='Concept Testing'!F35 -> Custom
B10: Competitive Benchmarking | D10: ='Competitive Benchmarking'!C35 -> $32,000 + n*(CPI*2.5+$1.68) | E10: ='Competitive Benchmarking'!D35 -> $36,000 + n*(CPI*2.5+$3.04) | F10: ='Competitive Benchmarking'!E35 -> $48,500 + n*(CPI*2.5+$3.04) | G10: ='Competitive Benchmarking'!F35 -> Custom
B11: Competitive Landscape / Market Landscape | D11: ='Competitive Landscape Market L'!C35 -> $21,000 + n*(CPI*2.5+$0.68) | E11: ='Competitive Landscape Market L'!D35 -> $29,500 + n*(CPI*2.5+$0.68) | F11: ='Competitive Landscape Market L'!E35 -> $37,500 + n*(CPI*2.5+$0.68) | G11: ='Competitive Landscape Market L'!F35 -> Custom
B12: Message Testing w MaxDiff | D12: ='Message Testing w MaxDiff'!C35 -> $26,000 + n*(CPI*2.5) | E12: ='Message Testing w MaxDiff'!D35 -> $29,000 + n*(CPI*2.5) | F12: ='Message Testing w MaxDiff'!E35 -> $40,000 + n*(CPI*2.5) | G12: ='Message Testing w MaxDiff'!F35 -> Custom
B13: Product Development w Conjoint | D13: ='Product Development w Conjoint'!C35 -> $33,000 + n*(CPI*2.5) | E13: ='Product Development w Conjoint'!D35 -> $41,500 + n*(CPI*2.5) | F13: ='Product Development w Conjoint'!E35 -> $43,500 + n*(CPI*2.5) | G13: ='Product Development w Conjoint'!F35 -> Custom
B14: Product Development w MaxDiff | D14: ='Product Development w MaxDiff'!C35 -> $26,000 + n*(CPI*2.5) | E14: ='Product Development w MaxDiff'!D35 -> $29,000 + n*(CPI*2.5) | F14: ='Product Development w MaxDiff'!E35 -> $40,000 + n*(CPI*2.5) | G14: ='Product Development w MaxDiff'!F35 -> Custom
B15: Segmentation | D15: =Segmentation!C35 -> $57,750 + n*(CPI*2.5) | E15: =Segmentation!D35 | F15: =Segmentation!E35 | G15: =Segmentation!F35 -> Custom
B17: Data Collection Details
B18: Enter Cost per Complete (CPI) to Qualtrics | D18: 3 | E18: <-- Enter CPI from vendors
B19: Margin percentage | D19: 0.6 | E19: <-- Min 60%
B20: Cost per Complete (CPI) to Client | D20: =max(D18/(1-D19),5) -> 7.5 | E20: Note, minumum $5 CPI to clients
B22: Enter Sample Size (n) | D22: 2000 | E22: <-- Enter desired sample size
B24: Base Costs + Data Collection Costs | D24: Tier 1 - Standard | E24: Tier 2 - Standard Plus | F24: Tier 3 - Advanced | G24: Tier 4 - Custom
B25: A&U | D25: =D35+$D$22*($D$20+0.68) -> 41260 | E25: =E35+$D$22*($D$20+0.68) -> 44760 | F25: =F35+$D$22*($D$20+0.68) -> 52260 | G25: =G6 -> Custom
B26: Ad Testing | D26: =D36+$D$22*($D$20+0.68) -> 40860 | E26: =E36+$D$22*($D$20+2.04) -> 46080 | F26: =F36+$D$22*($D$20+2.04) -> 51980 | G26: =G7 -> Custom
B27: Concept Testing | D27: =D38+$D$22*($D$20+0.68) -> 40860 | E27: =E38+$D$22*($D$20+2.04) -> 46080 | F27: =F38+$D$22*($D$20+2.04) -> 51980 | G27: =G9 -> Custom
B28: Competitive Benchmarking | D28: =D39+$D$22*($D$20+1.68) -> 50360 | E28: =E39+$D$22*($D$20+3.04) -> 57080 | F28: =F39+$D$22*($D$20+3.04) -> 69580 | G28: =G10 -> Custom
B29: Competitive Landscape / Market Landscape | D29: =D40+$D$22*($D$20+0.68) -> 37360 | E29: =E40+$D$22*($D$20+0.68) -> 45860 | F29: =F40+$D$22*($D$20+0.68) -> 53860 | G29: =G11 -> Custom
B30: Message Testing w MaxDiff | D30: =D41+$D$22*($D$20) -> 41000 | E30: =E41+$D$22*($D$20) -> 44000 | F30: =F41+$D$22*($D$20) -> 55000 | G30: =G12 -> Custom
B31: Product Development w Conjoint | D31: =D42+$D$22*($D$20) -> 48000 | E31: =E42+$D$22*($D$20) -> 56500 | F31: =F42+$D$22*($D$20) -> 58500 | G31: =G13 -> Custom
B32: Product Development w MaxDiff | D32: =D43+$D$22*($D$20) -> 41000 | E32: =E43+$D$22*($D$20) -> 44000 | F32: =F43+$D$22*($D$20) -> 55000 | G32: =G14 -> Custom
B33: Segmentation | D33: =D44+$D$22*($D$20) -> 72750 | E33: - | F33: - | G33: =G15 -> Custom
B35: A&U | D35: =left(D6,7) -> $24,900 | E35: =LEFT(E6,7) -> $28,400 | F35: =LEFT(F6,7) -> $35,900
B36: AdTesting | D36: =left(D7,7) -> $24,500 | E36: =LEFT(E7,7) -> $27,000 | F36: =LEFT(F7,7) -> $32,900
B37: Brand Tracking | D37: =left(D8,7) | E37: =LEFT(E8,7) | F37: =LEFT(F8,7)
B38: Concept Testing | D38: =left(D9,7) -> $24,500 | E38: =LEFT(E9,7) -> $27,000 | F38: =LEFT(F9,7) -> $32,900
B39: Competitive Benchmarking | D39: =left(D10,7) -> $32,000 | E39: =LEFT(E10,7) -> $36,000 | F39: =LEFT(F10,7) -> $48,500
B40: Competitive Landscape / Market Landscape | D40: =left(D11,7) -> $21,000 | E40: =LEFT(E11,7) -> $29,500 | F40: =LEFT(F11,7) -> $37,500
B41: Message Testing w MaxDiff | D41: =left(D12,7) -> $26,000 | E41: =LEFT(E12,7) -> $29,000 | F41: =LEFT(F12,7) -> $40,000
B42: Product Development w Conjoint | D42: =left(D13,7) -> $33,000 | E42: =LEFT(E13,7) -> $41,500 | F42: =LEFT(F13,7) -> $43,500
B43: Product Development w MaxDiff | D43: =left(D14,7) -> $26,000 | E43: =LEFT(E14,7) -> $29,000 | F43: =LEFT(F14,7) -> $40,000
B44: Segmentation | D44: =left(D15,7) -> $57,750 | E44: =LEFT(E15,7) | F44: =LEFT(F15,7)
B46: Add-Ons or Ad-Hoc
B47: Total Costs of Add-Ons or Ad-Hoc | D47: =sum(H50,H71,H94,H123, H141,H153) -> 0
B49: Add-Ons or Ad-Hoc Services | D49: Service | E49: Tier | F49: Needed Details | G49: Entered Details | H49: Additional Costs
...

Sheet A&U
A3: A&U | B3: A&U One- Pager | C3: Fundamental research aimed to guide brand development business growth by better understanding a market and identifying opportunities to expand reach, attract new consumers, improve brand/product positioning, and optimize product and service features. | G3: Return to Home
B6: XM Solution | C6: Tier 1 - Standard | D6: Tier 2 - Standard Plus | E6: Tier 3 - Advanced | F6: Tier 4 - Custom
A7: Overview | B7: N/A | C7: Smaller | D7: Added imagery and reporting | E7: More brands, imagery, more reporting, regression analysis
A9: Design and Build | C9: Survey Design & Build - Standard | D9: Survey Design & Build - Standard Plus | E9: Survey Design & Build - Advanced
C10: Up to 8 competitor brands | D10: Up to 8 competitor brands | E10: Up to 15 competitor brands
C11: Up to 10 imagery statements | D11: Up to 20 imagery statements | E11: Up to 20 imagery statements
C12: No translation | D12: No translation | E12: No translation
C13: No typing tool programmed | D13: No typing tool programmed | E13: No typing tool programmed
B18: - | C18: 8000 | D18: 11500 | E18: 14000 | F18: Custom
A20: Data Collection | C20: B2B or B2C Sample through Online Panel Partners with up to 3 quotas on completes | D20: B2B or B2C Sample through Online Panel Partners with up to 3 quotas on completes | E20: B2B or B2C Sample through Online Panel Partners with up to 3 quotas on completes | F20: B2B or B2C Sample through Online Panel Partners with up to 3 quotas on completes
B22: - | C22: CPI * 2.5 / complete | D22: CPI * 2.5 / complete | E22: CPI * 2.5 / complete | F22: CPI * 2.5 / complete
A24: Analysis & Reporting | C24: Reporting - Standard Plus | D24: Reporting - Standard Plus | E24: Reporting - Advanced
C25: Data Scrub - Standard | D25: Data Scrub - Standard | E25: Data Scrub - Standard
C26: Crosstabs - Standard | D26: Crosstabs - Standard | E26: Crosstabs - Standard
C27: No Dashboard | D27: No Dashboard | E27: No Dashboard
C28: No Typing Tool | D28: No Typing Tool | E28: No Typing Tool
C29: Open-Ended coding - Standard Plus, for 1 OE per Person | D29: Open-Ended coding - Standard Plus, for 1 OE per Person | E29: Open-Ended coding - Standard Plus, for 1 OE per Person
C30: No Weighting | D30: No Weighting | E30: No Weighting
C31: No Regression Analysis | D31: No Regression Analysis | E31: Optional Regression Analysis
C32: No market sizing analysis | D32: No market sizing analysis | E32: No market sizing analysis
B33: - | C33: $16,900 + $0.68 * n (for OE coding) | D33: $16,900 + $0.68 * n (for OE coding) | E33: $21,900 + $0.68 * n (for OE coding) | F33: Custom
A35: Total Base Costs | B35: - | C35: $24,900 + n*(CPI*2.5+$0.68) | D35: $28,400 + n*(CPI*2.5+$0.68) | E35: $35,900 + n*(CPI*2.5+$0.68) | F35: Custom
B37: Optional Add-Ons
B38: Item | C38: Description | D38: Added Costs
B40: Market Sizing Analysis | D40: 2000
B41: Luth Passive Metering
B42: MFour Behavioral Data
B43: Data Append - Advanced
B44: Data Append - Extra Advanced
B45: Translations - Standard Plus
B46: Translations - Advanced
B47: Data Collection - Standard Plus | D47: Add $1 / Complete
B48: Data Collection - Advanced | D48: Add $2 / Complete
B49: Open-Ended Coding - Standard Plus
B50: Back-End Translations - Standard Plus
B51: Back-End Translations - Advanced
B52: Data Weighting - Standard
B53: Data Weighting - Standard Plus
B54: Data Weighting - Advanced
B55: Typing Tool Programming - Standard | D55: 3000
...

Sheet Ad Testing
A3: Ad Testing | B3: Ad Testing One- Pager | C3: Testing advertisements, messaging, and content before it goes live in the market to mitigate the risk of an ineffective ad and ensure resonation with desired target audience. | G3: Return to Home
B6: XM Solution | C6: Tier 1 - Standard | D6: Tier 2 - Standard Plus | E6: Tier 3 - Advanced | F6: Tier 4 - Custom
A7: Overview | B7: =HYPERLINK("https://www.qualtrics.com/marketplace/creative-testing-study/","https://www.qualtrics.com/marketplace/advertising-creative-testing/") -> https://www.qualtrics.com/marketplace/advertising-creative-testing/ | C7: Ad Testing with Basic Reporting on a Smaller Set of Ads | D7: Ad Testing for a Larger Number of Ads | E7: Ad Testing with Additional Reporting | F7: Ad Testing with Custom Build Needs, Additional Analytics or Added Deliverables
B8: =HYPERLINK("https://www.qualtrics.com/marketplace/advertising-creative-testing/","https://www.qualtrics.com/marketplace/advertising-creative-testing/") -> https://www.qualtrics.com/marketplace/advertising-creative-testing/
A10: Design and Build | B10: An expert-built template preloaded with the right questions | C10: Survey Design & Build - Standard Plus | D10: Survey Design & Build - Advanced | E10: Survey Design & Build - Advanced
B11: Ph.D. designed methodology | C11: Sequential or Monadic Design | D11: Sequential or Monadic Design | E11: Sequential or Monadic Design
B12: Prebuilt logic and survey structure | C12: Up to 4 Ads (print ads or video ads) | D12: Up to 8 Ads (print ads or video ads) | E12: Up to 8 Ads (print ads or video ads)
B13: Automated workflow | C13: No translation | D13: No translation | E13: No translation
C14: No typing tool programmed | D14: No typing tool programmed | E14: No typing tool programmed
C15: Optional use of heatmap, hotspot, or highlighter tools | D15: Optional use of heatmap, hotspot, or highlighter tools | E15: Optional use of heatmap, hotspot, or highlighter tools
C16: Client must host videos or place on Vimeo/YouTube | D16: Client must host videos or place on Vimeo/YouTube | E16: Client must host videos or place on Vimeo/YouTube
B17: Creative Testing: Additional Fee Require License: Research Core 5
B19: Ad Creative Testing: Included in License Require License: Research Core 3 | C19: 11500 | D19: 14000 | E19: 14000 | F19: Custom
A21: Data Collection | B21: B2B or B2C Sample through Online Panel Partners with up to 3 quotas on completes | C21: B2B or B2C Sample through Online Panel Partners with up to 3 quotas on completes | D21: B2B or B2C Sample through Online Panel Partners with up to 3 quotas on completes | E21: B2B or B2C Sample through Online Panel Partners with up to 3 quotas on completes | F21: B2B or B2C Sample through Online Panel Partners with up to 3 quotas on completes
B23: CPI * 2.5 / complete | C23: CPI * 2.5 / complete | D23: CPI * 2.5 / complete | E23: CPI * 2.5 / complete | F23: CPI * 2.5 / complete
A25: Analysis & Reporting | B25: Pre Built reports | C25: Reporting - Standard | D25: Reporting - Standard | E25: Reporting - Standard Plus
C26: Data Scrub - Standard | D26: Data Scrub - Standard | E26: Data Scrub - Standard
C27: Crosstabs - Standard | D27: Crosstabs - Standard | E27: Crosstabs - Standard
C28: No Dashboard | D28: No Dashboard | E28: No Dashboard
C29: No Typing Tool | D29: No Typing Tool | E29: No Typing Tool
C30: Open-Ended coding - Standard Plus for 1 OE per Person | D30: Open-Ended coding - Standard Plus for 3 OE per Person | E30: Open-Ended coding Standard Plus for 3 OE per Person
C31: No Weighting | D31: No Weighting | E31: No Weighting
B32: Creative Testing: Additional Fee Require License: Research Core 5
B34: Ad Creative Testing: Included in License Require License: Research Core 3 | C34: $13,000 + $0.68 * n (for OE coding) | D34: $13,000 + $0.68 * 3n (for OE coding) | E34: $18,000 + $0.68 * n (for OE coding) | F34: Custom
A36: Total Base Costs | B36: - | C36: $24,500 + n*(CPI*2.5+$0.68) | D36: $27,000 + n*(CPI*2.5+$2.04) | E36: $32,900 + n*(CPI*2.5+$2.04) | F36: Custom
B38: Optional Add-Ons
B39: Item | C39: Description | D39: Added Costs
B40: Translations - Standard Plus
B41: Translations - Advanced
B42: Data Collection - Standard Plus | D42: Add $1 / Complete
B43: Data Collection - Advanced | D43: Add $2 / Complete
B44: Open-Ended Coding - Standard Plus
B45: Back-End Translations - Standard Plus
B46: Back-End Translations - Advanced
B47: Data Weighting - Standard
B48: Data Weighting - Standard Plus
B49: Data Weighting - Advanced
B50: Typing Tool Programming - Standard | D50: 3000
B51: Typing Tool Programming - Standard Plus | D51: 5000
B52: VoxPopMe
...

Sheet Concept Testing
A3: Concept Testing | B3: Concept Testing One- Pager | C3: The investigation of potential consumers reactions to a proposed product or service before introducing it to market. As businesses look to launch a product, concept testing is a valuable step to identify perceptions, wants, and needs associated with a product or service. | G3: Return to Home
B6: XM Solution | C6: Tier 1 - Standard | D6: Tier 2 - Standard Plus | E6: Tier 3 - Advanced | F6: Tier 4 - Custom
A7: Overview | B7: =HYPERLINK("https://www.qualtrics.com/marketplace/concept-testing-study/","https://www.qualtrics.com/marketplace/concept-testing-study/") -> https://www.qualtrics.com/marketplace/concept-testing-study/ | C7: Concept Testing with Basic Reporting on a Smaller Set of Concepts | D7: Concept Testing for a Larger Number of Concepts | E7: Concept Testing with Additional Reporting | F7: Concept Testing with Custom Build Needs, Additional Analytics or Added Deliverables
A9: Design and Build | B9: An expert-built template preloaded with the right questions | C9: Survey Design & Build - Standard Plus | D9: Survey Design & Build - Advanced | E9: Survey Design & Build - Advanced
B10: Ph.D. designed methodology | C10: Sequential or Monadic Design | D10: Sequential or Monadic Design | E10: Sequential or Monadic Design
B11: Prebuilt logic and survey structure | C11: Up to 4 Concepts | D11: Up to 8 Concepts | E11: Up to 8 Concepts
B12: Automated workflow | C12: No translation | D12: No translation | E12: No translation
C13: No typing tool programmed | D13: No typing tool programmed | E13: No typing tool programmed
C14: Optional use of heatmap, hotspot, or highlighter tools | D14: Optional use of heatmap, hotspot, or highlighter tools | E14: Optional use of heatmap, hotspot, or highlighter tools
B18: Included with License Require License: Research Core 3 | C18: 11500 | D18: 14000 | E18: 14000 | F18: Custom
A20: Data Collection | B20: B2B or B2C Sample through Online Panel Partners with up to 3 quotas on completes | C20: B2B or B2C Sample through Online Panel Partners with up to 3 quotas on completes | D20: B2B or B2C Sample through Online Panel Partners with up to 3 quotas on completes | E20: B2B or B2C Sample through Online Panel Partners with up to 3 quotas on completes | F20: B2B or B2C Sample through Online Panel Partners with up to 3 quotas on completes
B22: CPI * 2.5 / complete | C22: CPI * 2.5 / complete | D22: CPI * 2.5 / complete | E22: CPI * 2.5 / complete | F22: CPI * 2.5 / complete
A24: Analysis & Reporting | B24: Pre Built reports | C24: Reporting - Standard | D24: Reporting - Standard | E24: Reporting - Standard Plus
C25: Data Scrub - Standard | D25: Data Scrub - Standard | E25: Data Scrub - Standard
C26: Crosstabs - Standard | D26: Crosstabs - Standard | E26: Crosstabs - Standard
C27: No Dashboard | D27: No Dashboard | E27: No Dashboard
C28: No Typing Tool | D28: No Typing Tool | E28: No Typing Tool
C29: Open-Ended coding - Standard Plus for 1 OE per Person | D29: Open-Ended coding - Standard Plus for 3 OE per Person | E29: Open-Ended coding Standard Plus for 3 OE per Person
C30: No Weighting | D30: No Weighting | E30: No Weighting
B33: Included with License Require License: Research Core 3 | C33: $13,000 + $0.68 * n (for OE coding) | D33: $13,000 + $0.68 * 3n (for OE coding) | E33: $18,000 + $0.68 * n (for OE coding) | F33: 25000
A35: Total Base Costs | B35: - | C35: $24,500 + n*(CPI*2.5+$0.68) | D35: $27,000 + n*(CPI*2.5+$2.04) | E35: $32,900 + n*(CPI*2.5+$2.04) | F35: Custom
B37: Optional Add-Ons
B38: Item | C38: Description | D38: Added Costs
B39: Translations - Standard Plus
B40: Translations - Advanced
B41: Data Collection - Standard Plus | D41: Add $1 / Complete
B42: Data Collection - Advanced | D42: Add $2 / Complete
B43: Open-Ended Coding - Standard Plus
B44: Back-End Translations - Standard Plus
B45: Back-End Translations - Advanced
B46: Data Weighting - Standard
B47: Data Weighting - Standard Plus
B48: Data Weighting - Advanced
B49: Typing Tool Programming - Standard | D49: 3000
B50: Typing Tool Programming - Standard Plus | D50: 5000
B51: VoxPopMe
B52: Crosstabs - Standard Plus

Sheet Competitive Benchmarking
A3: Competitive Benchmarking | C3: Understanding customer satisfation, touchpoints, and interactions with a brand to allow comparison across all brands in the category. | G3: Return to Home
B6: XM Solution | C6: Tier 1 - Standard | D6: Tier 2 - Standard Plus | E6: Tier 3 - Advanced | F6: Tier 4 - Custom
A7: Overview | B7: N/A | C7: Moderate set of competitive brands with high level satisfaction metrics | D7: Moderate set of competitive brands with a deeper dive into products or touchpoint satisfaction | E7: Larger set of competitive brands with a deeper dive into products or touchpoint satisfaction. Includes dashboard.
A9: Design and Build | C9: Survey Design & Build - Standard Plus | D9: Survey Design & Build - Standard Plus | E9: Survey Design & Build - Advanced
C10: Up to 8 brands | D10: Up to 8 brands | E10: Up to 15 brands
C11: Up to 10 touchpoints/product types | D11: Up to 20 touchpoints/product types | E11: Up to 20 touchpoints/product types
C12: No translation | D12: No translation | E12: No translation
C13: No typing tool programmed | D13: No typing tool programmed | E13: No typing tool programmed
B18: - | C18: 11500 | D18: 11500 | E18: 14000 | F18: Custom
A20: Data Collection | C20: B2B or B2C Sample through Online Panel Partners with up to 5 quotas on completes OR nested quotas (2 variables) | D20: B2B or B2C Sample through Online Panel Partners with up to 5 quotas on completes OR nested quotas (2 variables) | E20: B2B or B2C Sample through Online Panel Partners with up to 5 quotas on completes OR nested quotas (2 variables) | F20: B2B or B2C Sample through Online Panel Partners with up to 5 quotas on completes OR nested quotas (2 variables)
B22: - | C22: (CPI * 2.5 + $1) / complete | D22: (CPI * 2.5 + $1) / complete | E22: (CPI * 2.5 + $1) / complete | F22: (CPI * 2.5 + $1) / complete
A24: Analysis & Reporting | C24: Reporting - Standard Plus | D24: Reporting - Advanced | E24: Reporting - Advanced
C25: Data Scrub - Standard | D25: Data Scrub - Standard | E25: Data Scrub - Standard
C26: Crosstabs - Standard | D26: Crosstabs - Standard Plus | E26: Crosstabs - Standard Plus
C27: No Dashboard | D27: No Dashboard | E27: Dashboard - Standard Plus
C28: No Typing Tool | D28: No Typing Tool | E28: No Typing Tool
C29: Open-Ended coding - Standard Plus for 1 OE per Person | D29: Open-Ended coding - Standard Plus for 3 OE per Person | E29: Open-Ended coding Standard Plus for 3 OE per Person
C30: No Weighting | D30: No Weighting | E30: No Weighting
C31: Optional Regression Analysis (1) | D31: Optional Regression Analysis (1) | E31: Optional Regression Analysis (1)
B33: - | C33: $20,500 + $0.68 * n (for OE coding) | D33: $24,500 + $2.04 * n (for OE coding) | E33: $34,500 + $2.04 * n (for OE coding) | F33: Custom
A35: Total Base Costs | B35: - | C35: $32,000 + n*(CPI*2.5+$1.68) | D35: $36,000 + n*(CPI*2.5+$3.04) | E35: $48,500 + n*(CPI*2.5+$3.04) | F35: Custom
B37: Optional Add-Ons
B38: Item | C38: Description | D38: Added Costs
B39: Regression Analysis | D39: 3000
B40: Translations - Standard Plus
B41: Translations - Advanced
B42: Data Collection - Standard Plus | D42: Add $1 / Complete
B43: Data Collection - Advanced | D43: Add $2 / Complete
B44: Open-Ended Coding - Standard Plus
B46: Dashboard - Advanced
B47: Back-End Translations - Standard Plus
B48: Back-End Translations - Advanced
B49: Data Appends - Advanced
B50: Data Appends - Extra Advanced
B51: Data Weighting - Standard
B52: Data Weighting - Standard Plus
B53: Data Weighting - Advanced

Sheet Competitive Landscape  Market L
A3: Competitive Landscape / Market Landscape | C3: Description | G3: Return to Home
B6: XM Solution | C6: Tier 1 - Standard | D6: Tier 2 - Standard Plus | E6: Tier 3 - Advanced | F6: Tier 4 - Custom
A7: Overview | B7: N/A | C7: Smaller | D7: Added imagery and reporting | E7: More brands, imagery, more reporting, regression analysis
A9: Design and Build | C9: Survey Design & Build - Standard | D9: Survey Design & Build - Standard Plus | E9: Survey Design & Build - Advanced
C10: Up to 8 brands | D10: Up to 8 brands | E10: Up to 15 brands
C11: Up to 10 imagery statements | D11: Up to 20 imagery statements | E11: Up to 20 imagery statements
C12: No translation | D12: No translation | E12: No translation
C13: No typing tool programmed | D13: No typing tool programmed | E13: No typing tool programmed
B18: - | C18: 8000 | D18: 11500 | E18: 14000 | F18: Custom
A20: Data Collection | C20: B2B or B2C Sample through Online Panel Partners with up to 3 quotas on completes | D20: B2B or B2C Sample through Online Panel Partners with up to 3 quotas on completes | E20: B2B or B2C Sample through Online Panel Partners with up to 3 quotas on completes | F20: B2B or B2C Sample through Online Panel Partners with up to 3 quotas on completes
B22: - | C22: CPI * 2.5 / complete | D22: CPI * 2.5 / complete | E22: CPI * 2.5 / complete | F22: CPI * 2.5 / complete
A24: Analysis & Reporting | C24: Reporting - Standard | D24: Reporting - Standard Plus | E24: Reporting - Advanced
C25: Data Scrub - Standard | D25: Data Scrub - Standard | E25: Data Scrub - Standard
C26: Crosstabs - Standard | D26: Crosstabs - Standard | E26: Crosstabs - Standard
C27: No Dashboard | D27: No Dashboard | E27: No Dashboard
C28: No Typing Tool | D28: No Typing Tool | E28: No Typing Tool
C29: Open-Ended coding - Standard Plus, for 1 OE per Person | D29: Open-Ended coding - Standard Plus, for 1 OE per Person | E29: Open-Ended coding - Standard Plus, for 1 OE per Person
C30: No Weighting | D30: No Weighting | E30: No Weighting
C31: No Regression Analysis | D31: No Regression Analysis | E31: Optional Regression Analysis (1)
C32: No market sizing analysis | D32: No market sizing analysis | E32: No market sizing analysis
B33: - | C33: $13,000 + $0.68 * n (for OE coding) | D33: $18,000 + $0.68 * n (for OE coding) | E33: $24,500 + $0.68 * n (for OE coding)
A35: Total Base Costs | B35: - | C35: $21,000 + n*(CPI*2.5+$0.68) | D35: $29,500 + n*(CPI*2.5+$0.68) | E35: $37,500 + n*(CPI*2.5+$0.68) | F35: Custom
B37: Optional Add-Ons
B38: Item | C38: Description | D38: Added Costs
B39: Regression Analysis | D39: 3000
B40: Translations - Standard Plus
B41: Translations - Advanced
B42: Data Collection - Standard Plus | D42: Add $1 / Complete
B43: Data Collection - Advanced | D43: Add $2 / Complete
B44: Open-Ended Coding - Standard Plus
B45: Factor Analysis
B46: Dashboard - Advanced
B47: Back-End Translations - Standard Plus
B48: Back-End Translations - Advanced
B49: Data Appends - Advanced
B50: Data Appends - Extra Advanced
B51: Data Weighting - Standard
B52: Data Weighting - Standard Plus
B53: Data Weighting - Advanced

Sheet Message Testing w MaxDiff
A3: Message Testing w/ MaxDiff | B3: Link to One- Pager | C3: With a MaxDiff methodology, we can test 10 to 25 potential messages and determine the optimal set messages to include in communications or across an advertisement campaign and maximize ROI during communication development and launch. | G3: Return to Home
A4: Note, pricing below is for full-service (end-to-end) only and includes a full survey build and PPT report in additional to the MaxDiff. Please see the "Ad-Hoc | Reporting & Analytics" tab for MaxDiff costs without other services.
B6: XM Solution | C6: Tier 1 - Standard | D6: Tier 2 - Standard Plus | E6: Tier 3 - Advanced | F6: Tier 4 - Custom
A7: Overview | B7: N/A | C7: MaxDiff with 8-20 statements and Standard Reportng | D7: MaxDiff with 8-20 statements and Reporting and TURF Analysis & Simulator | E7: MaxDiff with 8-20 statements with additional Analysis including Message Refinement, TURF Analysis & Simulator
A9: Design and Build | C9: Survey Design & Build - Standard | D9: Survey Design & Build - Standard | E9: Survey Design & Build - Standard Plus
C10: MaxDiff Design & Analysis - Standard | D10: MaxDiff Design & Analysis - Standard | E10: MaxDiff Design & Analysis - Standard Plus
C11: No Translation | D11: No Translation | E11: No Translation
C12: No typing tool programmed | D12: No typing tool programmed | E12: No typing tool programmed
E13: Message refinement via heatmap, hotspot, or highlighter tools
B18: - | C18: 13000 | D18: 13000 | E18: 19000 | F18: Custom
A20: Data Collection | C20: B2B or B2C Sample through Online Panel Partners with up to 3 quotas on completes | D20: B2B or B2C Sample through Online Panel Partners with up to 3 quotas on completes | E20: B2B or B2C Sample through Online Panel Partners with up to 3 quotas on completes | F20: B2B or B2C Sample through Online Panel Partners with up to 3 quotas on completes
B22: - | C22: CPI * 2.5 / complete | D22: CPI * 2.5 / complete | E22: CPI * 2.5 / complete | F22: CPI * 2.5 / complete
A24: Analysis & Reporting | C24: Reporting - Standard | D24: Reporting - Standard | E24: Reporting - Standard Plus
C25: Data Scrub - Standard | D25: Data Scrub - Standard | E25: Data Scrub - Standard
C26: Crosstabs - Standard | D26: Crosstabs - Standard | E26: Crosstabs - Standard
C27: MaxDiff Design & Analysis - Standard | D27: MaxDiff Design & Analysis - Standard | E27: MaxDiff Design & Analysis - Standard Plus
C28: No TURF Analysis | D28: TURF Analysis & Simulator | E28: TURF Analysis & Simulator
C29: No Dashboard | D29: No Dashboard | E29: No Dashboard
C30: No Typing Tool | D30: No Typing Tool | E30: No Typing Tool
C31: No Open-Ended coding | D31: No Open-Ended coding | E31: No Open-Ended coding
C32: No Weighting | D32: No Weighting | E32: No Weighting
B33: - | C33: 13000 | D33: 16000 | E33: 21000 | F33: Custom
A35: Total Base Costs | B35: - | C35: $26,000 + n*(CPI*2.5) | D35: $29,000 + n*(CPI*2.5) | E35: $40,000 + n*(CPI*2.5) | F35: Custom
B37: Optional Add-Ons
B38: Item | C38: Description | D38: Added Costs
B39: Translations - Standard Plus
B40: Translations - Advanced
B41: Data Collection - Standard Plus | D41: Add $1 / Complete
B42: Data Collection - Advanced | D42: Add $2 / Complete
B43: Open-Ended Coding - Standard Plus
B44: Back-End Translations - Standard Plus
B45: Back-End Translations - Advanced
B46: Data Weighting - Standard
B47: Data Weighting - Standard Plus
B48: Data Weighting - Advanced
B49: VoxPopMe

Sheet Product Development w Conjoint
A3: Product Development w/ Conjoint | B3: Link to One- Pager | C3: Conjoint analysis is an advanced analytic technique which assesses the importance consumers place on different features of a given product or service. | G3: Return to Home
A4: Note, pricing below is for full-service (end-to-end) only and includes a full survey build and PPT report in additional to the Conjoint. Please see the "Ad-Hoc | Reporting & Analytics" tab for Conjoint costs without other services.
B6: Conjoint Tool | C6: Tier 1 - Standard | D6: Tier 2 - Standard Plus | E6: Tier 3 - Advanced | F6: Tier 4 - Custom
A7: Overview | B7: =HYPERLINK("https://www.qualtrics.com/marketplace/conjoint-package-analysis/","https://www.qualtrics.com/marketplace/conjoint-package-analysis/") -> https://www.qualtrics.com/marketplace/conjoint-package-analysis/ | C7: Conjoint with 3-7 Features, each with 2-5 levels, a standard survey build around the conjoint, and basic reporting | D7: Conjoint with 3-7 Features, each with 2-5 levels, a more complex survey build around the conjoint and additional reporting | E7: More advanced conjoint with survey build and additional reporting
A9: Design and Build | B9: An expert-built template preloaded with the right questions | C9: Survey Design & Build - Standard | D9: Survey Design & Build - Standard Plus | E9: Survey Design & Build - Standard Plus
B10: Ph.D. designed methodology | C10: Conjoint Design & Analysis - Standard Plus | D10: Conjoint Design & Analysis - Standard Plus | E10: Conjoint Design & Analysis - Advanced
B11: Prebuilt logic and survey structure | C11: No Translation | D11: No Translation | E11: No Translation
B12: Automated workflow | C12: No typing tool programmed | D12: No typing tool programmed | E12: No typing tool programmed
B18: Additional Fee Required License: Research Core 3 | C18: 20000 | D18: 23500 | E18: 25500 | F18: Custom
A20: Data Collection | B20: B2B or B2C Sample through Online Panel Partners with up to 3 quotas on completes | C20: B2B or B2C Sample through Online Panel Partners with up to 3 quotas on completes | D20: B2B or B2C Sample through Online Panel Partners with up to 3 quotas on completes | E20: B2B or B2C Sample through Online Panel Partners with up to 3 quotas on completes | F20: B2B or B2C Sample through Online Panel Partners with up to 3 quotas on completes
B22: CPI * 2.5 / complete | C22: CPI * 2.5 / complete | D22: CPI * 2.5 / complete | E22: CPI * 2.5 / complete | F22: CPI * 2.5 / complete
A24: Analysis & Reporting | B24: Pre Built reports | C24: Reporting - Standard | D24: Reporting - Standard Plus | E24: Reporting - Standard Plus
C25: Data Scrub - Standard | D25: Data Scrub - Standard | E25: Data Scrub - Standard
C26: Crosstabs - Standard | D26: Crosstabs - Standard | E26: Crosstabs - Standard
C27: Conjoint Design & Analysis - Standard Plus | D27: Conjoint Design & Analysis - Standard Plus | E27: Conjoint Design & Analysis - Advanced
C28: No TURF Analysis | D28: No TURF Analysis | E28: No TURF Analysis
C29: No Dashboard | D29: No Dashboard | E29: No Dashboard
C30: No Typing Tool | D30: No Typing Tool | E30: No Typing Tool
C31: No Open-Ended coding | D31: No Open-Ended coding | E31: No Open-Ended coding
C32: No Weighting | D32: No Weighting | E32: No Weighting
B33: Additional Fee Required License: Research Core 3 | C33: 13000 | D33: 18000 | E33: 18000 | F33: Custom
A35: Total Base Costs | B35: - | C35: $33,000 + n*(CPI*2.5) | D35: $41,500 + n*(CPI*2.5) | E35: $43,500 + n*(CPI*2.5) | F35: Custom
B37: Optional Add-Ons
B38: Item | C38: Description | D38: Added Costs
B39: Translations - Standard Plus
B40: Translations - Advanced
B41: Data Collection - Standard Plus | D41: Add $1 / Complete
B42: Data Collection - Advanced | D42: Add $2 / Complete
B43: Open-Ended Coding - Standard Plus
B44: Back-End Translations - Standard Plus
B45: Back-End Translations - Advanced
B46: Data Weighting - Standard
B47: Data Weighting - Standard Plus
B48: Data Weighting - Advanced
B49: VoxPopMe
B50: TURF Analysis - Standard | D50: 2000
B51: TURF Analysis - Standard Plus | D51: 3000

Sheet Segmentation
A3: Segmentation | B3: =HYPERLINK("https://drive.google.com/file/d/1KLIqnSiRhfUMIG3X_P4wHpXKxQI0ZEac/view?usp=sharing","Segmentation One- Pager") -> Segmentation One- Pager | C3: Breaking up the overall market into clearly identifiable segments having similar wants and needs characteristics. A subset are often then selected as "target segments" based on their economic potential, as well as, receptivity to the brand. | G3: Return to Home
B6: XM Solution | C6: Tier 1 - Standard | D6: Tier 2 - Standard Plus | E6: Tier 3 - Advanced | F6: Tier 4 - Custom
A7: Overview | B7: N/A | C7: Standard Full-Service Segmentation with Reporting, CrossTabs and Typing Tool for Future Research | F7: Custom Segmentation Design and/or Analysis
A9: Design and Build | C9: Survey Design & Build - Advanced | F9: Tier 1, plus custom design needs
C10: No translations
B18: - | C18: 14000 | F18: Custom Quote
A20: Data Collection | C20: B2B or B2C Sample through Online Panel Partners with up to 3 quotas on completes | F20: B2B or B2C Sample through Online Panel Partners with up to 3 quotas on completes
B22: - | C22: CPI * 2.5 / complete | F22: CPI * 2.5 / complete
A24: Analysis & Reporting | C24: Reporting - Advanced | F24: Tier 1, plus custom analytic needs
C25: Data Scrub - Standard
C26: Crosstabs - Standard Plus
C27: Segmentation (Clustering Analysis)
C28: Importing of the Segment Variable
C29: No Dashboard
C30: Typing Tool
C31: No Open-Ended coding
C32: No Weighting
B33: - | C33: 43750 | F33: Custom Quote
A35: Total Base Costs | B35: - | C35: $57,750 + n*(CPI*2.5) | F35: Custom
B37: Optional Add-Ons
B38: Item | C38: Description | D38: Added Costs
B39: Market Sizing Analysis | D39: 2000
B40: Translations - Standard Plus
B41: Translations - Advanced
B42: Data Collection - Standard Plus | D42: Add $1 / Complete
B43: Data Collection - Advanced | D43: Add $2 / Complete
B44: Open-Ended Coding - Standard Plus | D44: $0.68 per complete
B45: Dashboard - Standard Plus
B46: Dashboard - Advanced
B47: Back-End Translations - Standard Plus
B48: Back-End Translations - Advanced
B49: Data Appends - Advanced
B50: Data Appends - Extra Advanced
B51: Data Weighting - Standard
B52: Data Weighting - Standard Plus
B53: Data Weighting - Advanced

Sheet Product Development w MaxDiff
A3: Product Development w/ MaxDiff | C3: With a MaxDiff methodology, we can test 10 to 25 potential product features and determine the optimal set features to include in product(s) to maximize consumer interest, volume, and revenue. | G3: Return to Home
A4: Note, pricing below is for full-service (end-to-end) only and includes a full survey build and PPT report in additional to the MaxDiff. Please see the "Ad-Hoc | Reporting & Analytics" tab for MaxDiff costs without other services.
B6: XM Solution | C6: Tier 1 - Standard | D6: Tier 2 - Standard Plus | E6: Tier 3 - Advanced | F6: Tier 4 - Custom
A7: Overview | B7: https://www.qualtrics.com/marketplace/max-diff-software-tool/ | C7: MaxDiff with 8-20 Product Features and Standard Reportng | D7: MaxDiff with 8-20 Product Features and Reporting and TURF Analysis & Simulator | E7: MaxDiff with 8-20 Product Features with additional Analysis including Feature Refinement, TURF Analysis & Simulator
A9: Design and Build | B9: An expert-built template preloaded with the right questions | C9: Survey Design & Build - Standard | D9: Survey Design & Build - Standard | E9: Survey Design & Build - Standard Plus
B10: Ph.D. designed methodology | C10: MaxDiff Design & Analysis - Standard Plus | D10: MaxDiff Design & Analysis - Standard Plus | E10: MaxDiff Design & Analysis - Standard Plus
B11: Prebuilt logic and survey structure | C11: No Translation | D11: No Translation | E11: No Translation
B12: Automated workflow | C12: No typing tool programmed | D12: No typing tool programmed | E12: No typing tool programmed
E13: Message refinement via heatmap, hotspot, or highlighter tools
B18: Additional Fee Required License: Research Core 3 | C18: 13000 | D18: 13000 | E18: 19000 | F18: Custom
A20: Data Collection | B20: B2B or B2C Sample through Online Panel Partners with up to 3 quotas on completes | C20: B2B or B2C Sample through Online Panel Partners with up to 3 quotas on completes | D20: B2B or B2C Sample through Online Panel Partners with up to 3 quotas on completes | E20: B2B or B2C Sample through Online Panel Partners with up to 3 quotas on completes | F20: B2B or B2C Sample through Online Panel Partners with up to 3 quotas on completes
B22: CPI * 2.5 / complete | C22: CPI * 2.5 / complete | D22: CPI * 2.5 / complete | E22: CPI * 2.5 / complete | F22: CPI * 2.5 / complete
A24: Analysis & Reporting | B24: Pre Built reports | C24: Reporting - Standard | D24: Reporting - Standard | E24: Reporting - Standard Plus
C25: Data Scrub - Standard | D25: Data Scrub - Standard | E25: Data Scrub - Standard
C26: Crosstabs - Standard | D26: Crosstabs - Standard | E26: Crosstabs - Standard
C27: MaxDiff Design & Analysis - Standard | D27: MaxDiff Design & Analysis - Standard | E27: MaxDiff Design & Analysis - Standard Plus
C28: No TURF Analysis | D28: TURF Analysis & Simulator | E28: TURF Analysis & Simulator
C29: No Dashboard | D29: No Dashboard | E29: No Dashboard
C30: No Typing Tool | D30: No Typing Tool | E30: No Typing Tool
C31: No Open-Ended coding | D31: No Open-Ended coding | E31: No Open-Ended coding
C32: No Weighting | D32: No Weighting | E32: No Weighting
B33: Additional Fee Required License: Research Core 3 | C33: 13000 | D33: 16000 | E33: 21000 | F33: Custom
A35: Total Base Costs | B35: - | C35: $26,000 + n*(CPI*2.5) | D35: $29,000 + n*(CPI*2.5) | E35: $40,000 + n*(CPI*2.5) | F35: Custom
B37: Optional Add-Ons
B38: Item | C38: Description | D38: Added Costs
B39: Translations - Standard Plus
B40: Translations - Advanced
B41: Data Collection - Standard Plus | D41: Add $1 / Complete
B42: Data Collection - Advanced | D42: Add $2 / Complete
B43: Open-Ended Coding - Standard Plus
B44: Back-End Translations - Standard Plus
B45: Back-End Translations - Advanced
B46: Data Weighting - Standard
B47: Data Weighting - Standard Plus
B48: Data Weighting - Advanced
B49: VoxPopMe

Sheet BX | Implementation & Services
A3: BX - Brand Tracking | B3: =HYPERLINK("https://success.qualtrics.com/rs/542-FMF-412/images/Brand%20Tracking%20Graphic.pdf","Qualtrics BX Infographic") -> Qualtrics BX Infographic | C3: Understand your market, your brand performance, and your competitors better than ever before. Qualtrics BrandXM™ gives you easy-to-use tools to help you: Strengthen brand equity Improve brand perceptions And drive sustainable growth | G3: Return to Home
B6: XM Solution | C6: Tier 1 - Standard | D6: Tier 2 - Standard Plus | E6: Tier 3 - NA | F6: Tier 4 - Custom
A7: Overview
A9: Design & Build
A10: Implementation | B10: N/A | F10: Custom quote required if: Multiple dashboards or builds Over 60 questions Multiple pathways or links Over 20 dashboard filters Large number of custom metrics Multiple data sources Other items not covered in Standard or Standard Plus
F11: Custom Quote
A14: Data Migration - Internal | B14: N/A | C14: Includes migrating 1 survey and 1 dashboard from CoreXM or CX to BX. Assumptions: Other than enabling these existing projects to have access to BX technology, no other survey or dashboard edits are included. Modifications outside of this migration require additional scoping and costs.
C15: 3000
A18: Data Migration - External | B18: N/A | C18: Includes migration from an external data source (CRM, sales data, etc.)
C19: Custom
A22: Survey Review & Consultation | B22: N/A | C22: Includes methodology review and consultation for: 1 survey in English Up to 30 questions 1 survey pathway (no differences by market/category) Up to 20 brands (including competitors) Up to 2 rounds of iteration (one round of customer marked-up feedback on question content, response options, or logic that impacts 5 or more questions) Assumptions: The customer provides a fully written out questionnaire, including demographics and screener questions. Bullets or partially written questions will require design services and an additional cost. The customer provides the questionnaire in a Word file, Google Doc, or similar format. Excel or Google Sheet formats will require additional scoping and costs. | D22: Includes methodology review and consultation for: 1 survey in English Up to 60 questions 1 survey pathway (no differences by market/category) Up to 20 brands (including competitors) Up to 3 rounds of iteration (one round of customer marked-up feedback on question content, response options, or logic that impacts 5 or more questions) Assumptions: The customer provides a fully written out questionnaire, including demographics and screener questions. Bullets or partially written questions will require design services and an additional cost. The customer provides the questionnaire in a Word file, Google Doc, or similar format. Excel or Google Sheet formats will require additional scoping and costs. | F22: Includes methodology review and consultation for: Multiple surveys Surveys over 60 questions Surveys with multiple pathways Other cases not covered in standard or standard plus
C23: 3000 | D23: 4500 | F23: Custom Quote
A26: Survey Design | B26: N/A | C26: Includes design for: 1 survey in English Up to 30 questions 1 survey pathway (no differences by market/category) Up to 20 brands (including competitors) Up to 10 brand attributes/imagery statements Up to 2 rounds of iteration (one round of customer marked-up feedback on question content, response options, or logic that impacts 5 or more questions) Includes design consultation on dashboard layout and content Estimated Timing: 1-2 weeks | D26: Includes design for: 1 survey in English Up to 60 questions 1 survey pathway (no differences by market/category) Up to 20 brands (including competitors) Up to 20 brand attributes/imagery statements Up to 3 rounds of iteration (one round of customer marked-up feedback on question content, response options, or logic that impacts 5 or more questions) Includes design consultation on dashboard layout and content Estimated Timing: 1-2 weeks | F26: Includes survey design for: Multiple surveys Surveys over 60 questions Surveys with multiple pathways Other cases not covered in standard or standard plus
C27: 6000 | D27: 8000 | F27: Custom Quote
A30: Consultation Services - Research Experts | B30: N/A | C30: Research Analyst or Specialist Customer may engage a Qualtrics research expert for survey programming, dashboard programming, analytics support, data consultation and data interpretation. | D30: Research Manager Customer may engage a Qualtrics research manager for analytics support, data consultation and data interpretation.
C31: $250 per hour | D31: $350 per hour
A33: Consultation Services - XM Scientists | B33: N/A | C33: Customer may engage a Qualtrics XMS for methodology or analytics advice and consultation.
C34: $350 per hour
A36: Consultation Services - Tech Consultant | B36: N/A | C36: Customer may engage a Qualtrics technology consultation for survey programming and dashboard programming.
C37: $250 per hour
A39: BX Ongoing Success Packages: Base | B39: N/A | C39: Support on BX Licenses which includes: Standard Product Support & Customer Success
A40: Customer Profile: Stable program, declines support and willing to be self-sufficient; typically <$60k in spend | C40: Included with all BX licenses (CSM coverage varies by spend tier and included only if license spend >$50k) | F40: Custom Quote
A42: BX Ongoing Success Packages: Guided | B42: N/A | C42: Support on BX Licenses which includes: Standard Product Support & Customer Success Quarterly consulting retainer for up to 5 hours per quarter that could be used for: Minor question or dashboard edits Data interpretation and consulting Thought partnership | D42: Support on BX Licenses which includes: Standard Product Support & Customer Success Quarterly consulting retainer for up to 10 hours per quarter that could be used for: Minor question or dashboard edits Data interpretation and consulting Thought partnership | E42: Support on BX Licenses which includes: Standard Product Support & Customer Success Quarterly consulting retainer for up to 15 hours per quarter that could be used for: Minor question or dashboard edits Data interpretation and consulting Thought partnership
A43: Customer Profile: Moderate complexity programs, likely to require light updates and assistance | C43: $6,000/year | D43: $12,000/year | E43: $18,000/year | F43: Custom Quote
A45: BX Ongoing Success Packages: Advanced | B45: N/A | C45: Support on BX Licenses which includes: Standard Product Support & Customer Success Quarterly consulting retainer for up to 10 hours per quarter that could be used for: Minor question or dashboard edits Data intepretation and consulting Thought partnership Technical Account Manager, to provide higher level of program-specific platform support and configuration updates, for up to 5 hours per week
A46: Customer Profile: Highly complex enterprise programs with need for ongoing designated platform support | C46: $62,000/year ($50,000 for TAM, $12,000 for Consulting) | F46: Custom Quote

Sheet Core XM | Implementation & Serv
A3: Core XM Implementation and Services | B3: CoreXM Delivery Package Detail | G3: Return to Home
B6: Self-Service | C6: Tier 1 - Standard | D6: Tier 2 - Standard Plus | E6: Tier 3 - Advanced | F6: Tier 4 - Custom
A7: Overview
A9: Design & Build
A10: CoreXM Implementation | B10: Small to midsize orgs using internal resources with Business Edition $0-100K ARR, no add-ons | C10: Standard Delivery Package Implementation designed for midsize orgs using in house resources. Business Edition ($50k-$100k) License Tier. Includes: Project Management Kickoff call Pre-launch review Up to 8 hours of designated project consultant Estimated timeline: 4 weeks | D10: Standard Plus Delivery Package Implementation designed for larger programs, 1-2 use cases, growing internal capabilities Business Edition (up to $100k) License Tier. Includes: Project Management Kickoff call Pre-launch review Detailed project plan Up to 16 hours of designated project consultant Estimated timeline: 8 weeks | E10: Enterprise Essentials Delivery Package Implementation designed for Complex XM programs Multiple use cases. Involves consultation and implementation Business Edition (over $100k) License Tier. Enterprise Edition Under $1M ARR Includes: Project Management Kickoff call Pre-launch review Detailed project plan Up to TBD hours of designated project consultant Estimated timeline: TBD weeks | F10: Enterprise Premier Delivery Package Implementation designed for Complex XM programs with Multiple use cases that Require high-touch. Involves Premium consultation and implementation Enterprise Edition Over $1M ARR Includes: Project Management Kickoff call Pre-launch review Detailed project plan Up to TBD hours of designated project consultant Estimated timeline: TBD weeks
C11: 2000 | D11: 4000 | E11: Custom | F11: Custom
A14: Custom XM Solutions | B14: N/A | C14: Creation of a Custom XM Solution which includes Design & Build, Guided Interface Set-Up, and Creation of Report Templates. Specifically, this includes: Up to survey 20 questions Light survey flow logic Design review and consultation No tie in with MaxDiff, Conjoint, or other advanced analytic tools Guided interface 5 pre-built report pages with no custom widgets Up to 2 iterations per deliverable | D14: Creation of a Custom XM Solution which includes Design & Build, Guided Interface Set-Up, and Creation of Report Templates. Specifically, this includes: Up to survey 40 questions Moderate survey flow logic Design review and consultation No tie in with MaxDiff, Conjoint, or other advanced analytic tools Guided interface 10 pre-built report pages with no custom widgets Up to 2 iterations per deliverable | E14: Creation of a Custom XM Solution which includes Design & Build, Guided Interface Set-Up, and Creation of Report Templates. Specifically, this includes: Up to survey 60 questions Complex survey flow logic Design review and consultation No tie in with MaxDiff, Conjoint, or other advanced analytic tools Guided interface 15 pre-built report pages with no custom widgets Up to 3 iterations per deliverable | F14: Creation of a Custom XM Solution which includes Design & Build, Guided Interface Set-Up, and Creation of Report Templates. Custom scope required for surveys over 60 questions, requiring over 15 report pages, requiring custom widgets, involving a dashboard or more advance reporting, etc.
A15: Note: CoreXM5 license required to create | C15: 20000 | D15: 30000 | E15: 35000 | F15: Custom Quote
A18: Solution Configuration Updates (Add-on) | B18: N/A | C18: Updates to the Survey Design & Build, Guided Interface, and Report Templates Deliverables - Up to 20% change in each component performed under the respective Deliverable (Survey Design &amp; Build, Guided Interface, and Report Templates) - All requests must be presented together with each update - Up to 2 iterations for each deliverable, per instance of updates - Provided in English | F18: Updates to the Survey Design & Build, Guided Interface, and Report Templates Deliverables - Up to 20% change in each component performed under the respective Deliverable (Survey Design &amp; Build, Guided Interface, and Report Templates) - All requests must be presented together with each update - Up to 2 iterations for each deliverable, per instance of updates - Provided in English
A19: Note: CoreXM5 license required to edit | C19: Custom Quote | F19: Custom Quote
A22: Additional Dashboard Configuration (price per dashboard) | B22: N/A | C22: Support for Standard Survey: Support client’s build of survey with max 30 Questions, 30 Embedded Data Fields; Standard Dashboard Build: Max 20 widgets/survey, max 60 widgets total, max 3 roles
C23: 2500
A26: Additional Support | B26: N/A | C26: Additional SI Intercept Setup (price per intercept, each on a single domain or app): $500 Additional Site Intercept Support (per domain or app, includes one intercept): $2,500 Additional Survey Support (<30 questions, price per survey): $1,500 Additional Survey Support (30-60 questions, price per survey): $3,000 Developer Tools Advanced Support (Must be sold in conjunction with DeveloperTools Introductory Support): $3,000 XM Directory Automations Support (price per automation): $1,000
C27: $500 - $3000
A30: Batch user creation | B30: N/A | C30: User creation of up to 1000 users
C31: 1000
A34: Translation support | B34: N/A | C34: Dashboard Translation Support (price per dashboard, per language): $1,000 Survey Translation Support (price per survey, per language): $1,000
C35: 1000
A38: Data migration | B38: N/A | C38: Data Migration (per source, up to 50k responses each)
C39: 2000
A42: Custom Training/Demo | B42: N/A | C42: Custom Training/Demo (price per 1-hour session)
C43: 400

Sheet Ad-Hoc | Design and Build
A3: Ad-Hoc | Design and Build | C3: Prepping a survey for data collection by ensuring a sound design and methodology, building in Qualtrics and/or translating into other languages. | G3: Return to Home
B6: XM Solution | C6: Tier 1 - Standard | D6: Tier 2 - Standard Plus | E6: Tier 3 - Advanced | F6: Tier 4 - Custom
A7: Overview
A9: Design & Build
A10: Methodology Review and Consultation | B10: N/A | C10: Qualtrics will review one (1) survey for Customer. Such survey review will include: Up to 30 questions (each individual statement in a matrix or similar format counts as a question) Unless otherwise agreed, such survey review will not include: Technical review or testing Survey build or survey programming edits Delivery Team Responsibilities: If necessary, conduct kick-off call to discuss research objectives. Provide methodological expertise on best design practices and technical expertise on what is feasible in the platform. Conduct Quality Assurance (QA) for Customer's survey design. Share recommendations for Customer review. Customer Responsibilities: Provide a fully written out questionnaire, including demographics and screener questions. Bullets or partially written questions will be subject to additional fees and further scoping by Qualtrics. Provide the questionnaire in a .doc file, Google Doc, or similar format. Spreadsheet formats (.xls, Google Sheets, etc.) will be subject to additional fees and further scoping by Qualtrics. Assumptions: After initial survey recommendations are shared, Customer may request up to 2 rounds of iteration for review (Customer marked-up feedback on question content, response options, or logic that impacts 5 or more questions) Estimated Timing: 3-5 business days | D10: Qualtrics will review one (1) survey for Customer. Such survey review will include: Up to 60 questions (each individual statement in a matrix or similar format counts as a question) Unless otherwise agreed, such survey review will not include: Technical review or testing Survey build or survey programming edits Delivery Team Responsibilities: If necessary, conduct kick-off call to discuss research objectives. Provide methodological expertise on best design practices and technical expertise on what is feasible in the platform. Conduct Quality Assurance (QA) for Customer's survey design. Share recommendations for Customer review. Customer Responsibilities: Provide a fully written out questionnaire, including demographics and screener questions. Bullets or partially written questions will be subject to additional fees and further scoping by Qualtrics. Provide the questionnaire in a .doc file, Google Doc, or similar format. Spreadsheet formats (.xls, Google Sheets, etc.) will be subject to additional fees and further scoping by Qualtrics. Assumptions: After initial survey recommendations are shared, Customer may request up to 3 rounds of iteration for review (Customer marked-up feedback on question content, response options, or logic that impacts 5 or more questions) Estimated Timing: 3-5 business days | E10: Qualtrics will review one (1) survey for Customer. Such survey review will include: Up to 100 questions (each individual statement in a matrix or similar format counts as a question) Unless otherwise agreed, such survey review will not include: Technical review or testing Survey build or survey programming edits Delivery Team Responsibilities: If necessary, conduct kick-off call to discuss research objectives. Provide methodological expertise on best design practices and technical expertise on what is feasible in the platform. Conduct Quality Assurance (QA) for Customer's survey design. Share recommendations for Customer review. Customer Responsibilities: Provide a fully written out questionnaire, including demographics and screener questions. Bullets or partially written questions will be subject to additional fees and further scoping by Qualtrics. Provide the questionnaire in a .doc file, Google Doc, or similar format. Spreadsheet formats (.xls, Google Sheets, etc.) will be subject to additional fees and further scoping by Qualtrics. Assumptions: After initial survey recommendations are shared, Customer may request up to 4 rounds of iteration for review (Customer marked-up feedback on question content, response options, or logic that impacts 5 or more questions) Estimated Timing: 5-7 business days | F10: Custom quote for multiple surveys, review of a translated survey, or advanced consultation needs
C11: 2100 | D11: 3100 | E11: 5100 | F11: Custom Quote
A12: *Bundled with Reporting | C12: 2000 | D12: 3000 | E12: 5000
C13: SRC-01 | D13: SRC-02 | E13: SRC-03 | F13: SRC-04
